2024-05-06 16:29:12,431 INFO    StreamThr :76774 [internal.py:wandb_internal():86] W&B internal server running at pid: 76774, started at: 2024-05-06 16:29:12.430152
2024-05-06 16:29:12,434 DEBUG   HandlerThread:76774 [handler.py:handle_request():146] handle_request: status
2024-05-06 16:29:12,441 INFO    WriterThread:76774 [datastore.py:open_for_write():87] open: /home/leverimmy/documents/Introduction-to-Artificial-Intelligence/Classification/src/wandb/run-20240506_162912-6twq6bfg/run-6twq6bfg.wandb
2024-05-06 16:29:12,441 DEBUG   SenderThread:76774 [sender.py:send():379] send: header
2024-05-06 16:29:12,448 DEBUG   SenderThread:76774 [sender.py:send():379] send: run
2024-05-06 16:29:15,493 INFO    SenderThread:76774 [retry.py:__call__():172] Retry attempt failed:
Traceback (most recent call last):
  File "/home/leverimmy/anaconda3/lib/python3.11/site-packages/urllib3/connection.py", line 174, in _new_conn
    conn = connection.create_connection(
           ^^^^^^^^^^^^^^^^^^^^^^^^^^^^^
  File "/home/leverimmy/anaconda3/lib/python3.11/site-packages/urllib3/util/connection.py", line 72, in create_connection
    for res in socket.getaddrinfo(host, port, family, socket.SOCK_STREAM):
               ^^^^^^^^^^^^^^^^^^^^^^^^^^^^^^^^^^^^^^^^^^^^^^^^^^^^^^^^^^
  File "/home/leverimmy/anaconda3/lib/python3.11/socket.py", line 962, in getaddrinfo
    for res in _socket.getaddrinfo(host, port, family, type, proto, flags):
               ^^^^^^^^^^^^^^^^^^^^^^^^^^^^^^^^^^^^^^^^^^^^^^^^^^^^^^^^^^^
socket.gaierror: [Errno -3] Temporary failure in name resolution

During handling of the above exception, another exception occurred:

Traceback (most recent call last):
  File "/home/leverimmy/anaconda3/lib/python3.11/site-packages/urllib3/connectionpool.py", line 714, in urlopen
    httplib_response = self._make_request(
                       ^^^^^^^^^^^^^^^^^^^
  File "/home/leverimmy/anaconda3/lib/python3.11/site-packages/urllib3/connectionpool.py", line 403, in _make_request
    self._validate_conn(conn)
  File "/home/leverimmy/anaconda3/lib/python3.11/site-packages/urllib3/connectionpool.py", line 1053, in _validate_conn
    conn.connect()
  File "/home/leverimmy/anaconda3/lib/python3.11/site-packages/urllib3/connection.py", line 363, in connect
    self.sock = conn = self._new_conn()
                       ^^^^^^^^^^^^^^^^
  File "/home/leverimmy/anaconda3/lib/python3.11/site-packages/urllib3/connection.py", line 186, in _new_conn
    raise NewConnectionError(
urllib3.exceptions.NewConnectionError: <urllib3.connection.HTTPSConnection object at 0x7fd82d60dd50>: Failed to establish a new connection: [Errno -3] Temporary failure in name resolution

During handling of the above exception, another exception occurred:

Traceback (most recent call last):
  File "/home/leverimmy/anaconda3/lib/python3.11/site-packages/requests/adapters.py", line 486, in send
    resp = conn.urlopen(
           ^^^^^^^^^^^^^
  File "/home/leverimmy/anaconda3/lib/python3.11/site-packages/urllib3/connectionpool.py", line 798, in urlopen
    retries = retries.increment(
              ^^^^^^^^^^^^^^^^^^
  File "/home/leverimmy/anaconda3/lib/python3.11/site-packages/urllib3/util/retry.py", line 592, in increment
    raise MaxRetryError(_pool, url, error or ResponseError(cause))
urllib3.exceptions.MaxRetryError: HTTPSConnectionPool(host='api.wandb.ai', port=443): Max retries exceeded with url: /graphql (Caused by NewConnectionError('<urllib3.connection.HTTPSConnection object at 0x7fd82d60dd50>: Failed to establish a new connection: [Errno -3] Temporary failure in name resolution'))

During handling of the above exception, another exception occurred:

Traceback (most recent call last):
  File "/home/leverimmy/anaconda3/lib/python3.11/site-packages/wandb/sdk/lib/retry.py", line 131, in __call__
    result = self._call_fn(*args, **kwargs)
             ^^^^^^^^^^^^^^^^^^^^^^^^^^^^^^
  File "/home/leverimmy/anaconda3/lib/python3.11/site-packages/wandb/sdk/internal/internal_api.py", line 369, in execute
    return self.client.execute(*args, **kwargs)  # type: ignore
           ^^^^^^^^^^^^^^^^^^^^^^^^^^^^^^^^^^^^
  File "/home/leverimmy/anaconda3/lib/python3.11/site-packages/wandb/vendor/gql-0.2.0/wandb_gql/client.py", line 52, in execute
    result = self._get_result(document, *args, **kwargs)
             ^^^^^^^^^^^^^^^^^^^^^^^^^^^^^^^^^^^^^^^^^^^
  File "/home/leverimmy/anaconda3/lib/python3.11/site-packages/wandb/vendor/gql-0.2.0/wandb_gql/client.py", line 60, in _get_result
    return self.transport.execute(document, *args, **kwargs)
           ^^^^^^^^^^^^^^^^^^^^^^^^^^^^^^^^^^^^^^^^^^^^^^^^^
  File "/home/leverimmy/anaconda3/lib/python3.11/site-packages/wandb/sdk/lib/gql_request.py", line 58, in execute
    request = self.session.post(self.url, **post_args)
              ^^^^^^^^^^^^^^^^^^^^^^^^^^^^^^^^^^^^^^^^
  File "/home/leverimmy/anaconda3/lib/python3.11/site-packages/requests/sessions.py", line 637, in post
    return self.request("POST", url, data=data, json=json, **kwargs)
           ^^^^^^^^^^^^^^^^^^^^^^^^^^^^^^^^^^^^^^^^^^^^^^^^^^^^^^^^^
  File "/home/leverimmy/anaconda3/lib/python3.11/site-packages/requests/sessions.py", line 589, in request
    resp = self.send(prep, **send_kwargs)
           ^^^^^^^^^^^^^^^^^^^^^^^^^^^^^^
  File "/home/leverimmy/anaconda3/lib/python3.11/site-packages/requests/sessions.py", line 703, in send
    r = adapter.send(request, **kwargs)
        ^^^^^^^^^^^^^^^^^^^^^^^^^^^^^^^
  File "/home/leverimmy/anaconda3/lib/python3.11/site-packages/requests/adapters.py", line 519, in send
    raise ConnectionError(e, request=request)
requests.exceptions.ConnectionError: HTTPSConnectionPool(host='api.wandb.ai', port=443): Max retries exceeded with url: /graphql (Caused by NewConnectionError('<urllib3.connection.HTTPSConnection object at 0x7fd82d60dd50>: Failed to establish a new connection: [Errno -3] Temporary failure in name resolution'))
2024-05-06 16:29:17,450 DEBUG   HandlerThread:76774 [handler.py:handle_request():146] handle_request: keepalive
2024-05-06 16:29:22,451 DEBUG   HandlerThread:76774 [handler.py:handle_request():146] handle_request: keepalive
2024-05-06 16:29:27,453 DEBUG   HandlerThread:76774 [handler.py:handle_request():146] handle_request: keepalive
2024-05-06 16:29:32,455 DEBUG   HandlerThread:76774 [handler.py:handle_request():146] handle_request: keepalive
2024-05-06 16:29:37,456 DEBUG   HandlerThread:76774 [handler.py:handle_request():146] handle_request: keepalive
2024-05-06 16:29:42,458 DEBUG   HandlerThread:76774 [handler.py:handle_request():146] handle_request: keepalive
2024-05-06 16:29:47,459 DEBUG   HandlerThread:76774 [handler.py:handle_request():146] handle_request: keepalive
2024-05-06 16:29:52,461 DEBUG   HandlerThread:76774 [handler.py:handle_request():146] handle_request: keepalive
2024-05-06 16:29:57,463 DEBUG   HandlerThread:76774 [handler.py:handle_request():146] handle_request: keepalive
2024-05-06 16:30:02,464 DEBUG   HandlerThread:76774 [handler.py:handle_request():146] handle_request: keepalive
2024-05-06 16:30:07,466 DEBUG   HandlerThread:76774 [handler.py:handle_request():146] handle_request: keepalive
2024-05-06 16:30:12,467 DEBUG   HandlerThread:76774 [handler.py:handle_request():146] handle_request: keepalive
2024-05-06 16:30:17,469 DEBUG   HandlerThread:76774 [handler.py:handle_request():146] handle_request: keepalive
2024-05-06 16:30:22,471 DEBUG   HandlerThread:76774 [handler.py:handle_request():146] handle_request: keepalive
2024-05-06 16:30:27,472 DEBUG   HandlerThread:76774 [handler.py:handle_request():146] handle_request: keepalive
2024-05-06 16:30:32,474 DEBUG   HandlerThread:76774 [handler.py:handle_request():146] handle_request: keepalive
2024-05-06 16:30:37,476 DEBUG   HandlerThread:76774 [handler.py:handle_request():146] handle_request: keepalive
2024-05-06 16:30:42,477 DEBUG   HandlerThread:76774 [handler.py:handle_request():146] handle_request: cancel
2024-05-06 16:30:42,477 DEBUG   HandlerThread:76774 [handler.py:handle_request():146] handle_request: cancel
2024-05-06 16:30:42,478 DEBUG   SenderThread:76774 [sender.py:send():388] Record cancelled: run
2024-05-06 16:30:42,479 DEBUG   HandlerThread:76774 [handler.py:handle_request():146] handle_request: status_report
2024-05-06 16:30:42,503 DEBUG   HandlerThread:76774 [handler.py:handle_request():146] handle_request: shutdown
2024-05-06 16:30:42,503 INFO    HandlerThread:76774 [handler.py:finish():866] shutting down handler
2024-05-06 16:30:43,479 INFO    SenderThread:76774 [sender.py:finish():1546] shutting down sender
2024-05-06 16:30:43,479 INFO    WriterThread:76774 [datastore.py:close():296] close: /home/leverimmy/documents/Introduction-to-Artificial-Intelligence/Classification/src/wandb/run-20240506_162912-6twq6bfg/run-6twq6bfg.wandb
