2024-04-27 02:04:06,938 INFO    StreamThr :7060 [internal.py:wandb_internal():86] W&B internal server running at pid: 7060, started at: 2024-04-27 02:04:06.937205
2024-04-27 02:04:06,940 DEBUG   HandlerThread:7060 [handler.py:handle_request():146] handle_request: status
2024-04-27 02:04:06,960 INFO    WriterThread:7060 [datastore.py:open_for_write():87] open: E:\Codes\Projects\Introduction-to-Artificial-Intelligence\Classification\src\wandb\run-20240427_020406-ecmgq4d8\run-ecmgq4d8.wandb
2024-04-27 02:04:06,961 DEBUG   SenderThread:7060 [sender.py:send():379] send: header
2024-04-27 02:04:07,466 DEBUG   SenderThread:7060 [sender.py:send():379] send: run
2024-04-27 02:04:08,192 ERROR   SenderThread:7060 [internal_api.py:execute():373] 404 response executing GraphQL.
2024-04-27 02:04:08,193 ERROR   SenderThread:7060 [internal_api.py:execute():374] {"errors":[{"message":"entity Ze-en Xiong not found during upsertBucket","path":["upsertBucket"]}],"data":{"upsertBucket":null}}
2024-04-27 02:04:08,193 ERROR   SenderThread:7060 [sender.py:send_run():971] It appears that you do not have permission to access the requested resource. Please reach out to the project owner to grant you access. If you have the correct permissions, verify that there are no issues with your networking setup.(Error 404: Not Found)
Traceback (most recent call last):
  File "D:\ProgramFiles\Python\Python312\Lib\site-packages\wandb\sdk\lib\retry.py", line 131, in __call__
    result = self._call_fn(*args, **kwargs)
             ^^^^^^^^^^^^^^^^^^^^^^^^^^^^^^
  File "D:\ProgramFiles\Python\Python312\Lib\site-packages\wandb\sdk\internal\internal_api.py", line 369, in execute
    return self.client.execute(*args, **kwargs)  # type: ignore
           ^^^^^^^^^^^^^^^^^^^^^^^^^^^^^^^^^^^^
  File "D:\ProgramFiles\Python\Python312\Lib\site-packages\wandb\vendor\gql-0.2.0\wandb_gql\client.py", line 52, in execute
    result = self._get_result(document, *args, **kwargs)
             ^^^^^^^^^^^^^^^^^^^^^^^^^^^^^^^^^^^^^^^^^^^
  File "D:\ProgramFiles\Python\Python312\Lib\site-packages\wandb\vendor\gql-0.2.0\wandb_gql\client.py", line 60, in _get_result
    return self.transport.execute(document, *args, **kwargs)
           ^^^^^^^^^^^^^^^^^^^^^^^^^^^^^^^^^^^^^^^^^^^^^^^^^
  File "D:\ProgramFiles\Python\Python312\Lib\site-packages\wandb\sdk\lib\gql_request.py", line 59, in execute
    request.raise_for_status()
  File "D:\ProgramFiles\Python\Python312\Lib\site-packages\requests\models.py", line 1021, in raise_for_status
    raise HTTPError(http_error_msg, response=self)
requests.exceptions.HTTPError: 404 Client Error: Not Found for url: https://api.wandb.ai/graphql

During handling of the above exception, another exception occurred:

Traceback (most recent call last):
  File "D:\ProgramFiles\Python\Python312\Lib\site-packages\wandb\sdk\internal\sender.py", line 969, in send_run
    server_run = self._init_run(run, config_value_dict)
                 ^^^^^^^^^^^^^^^^^^^^^^^^^^^^^^^^^^^^^^
  File "D:\ProgramFiles\Python\Python312\Lib\site-packages\wandb\sdk\internal\sender.py", line 1014, in _init_run
    server_run, inserted, server_messages = self._api.upsert_run(
                                            ^^^^^^^^^^^^^^^^^^^^^
  File "D:\ProgramFiles\Python\Python312\Lib\site-packages\wandb\apis\normalize.py", line 73, in wrapper
    raise err
  File "D:\ProgramFiles\Python\Python312\Lib\site-packages\wandb\apis\normalize.py", line 41, in wrapper
    return func(*args, **kwargs)
           ^^^^^^^^^^^^^^^^^^^^^
  File "D:\ProgramFiles\Python\Python312\Lib\site-packages\wandb\sdk\internal\internal_api.py", line 2217, in upsert_run
    response = self.gql(
               ^^^^^^^^^
  File "D:\ProgramFiles\Python\Python312\Lib\site-packages\wandb\sdk\internal\internal_api.py", line 341, in gql
    ret = self._retry_gql(
          ^^^^^^^^^^^^^^^^
  File "D:\ProgramFiles\Python\Python312\Lib\site-packages\wandb\sdk\lib\retry.py", line 147, in __call__
    retry_timedelta_triggered = check_retry_fn(e)
                                ^^^^^^^^^^^^^^^^^
  File "D:\ProgramFiles\Python\Python312\Lib\site-packages\wandb\util.py", line 968, in check_retry_fn
    return fallback_retry_fn(e)
           ^^^^^^^^^^^^^^^^^^^^
  File "D:\ProgramFiles\Python\Python312\Lib\site-packages\wandb\util.py", line 910, in no_retry_auth
    raise CommError(
wandb.errors.CommError: It appears that you do not have permission to access the requested resource. Please reach out to the project owner to grant you access. If you have the correct permissions, verify that there are no issues with your networking setup.(Error 404: Not Found)
2024-04-27 02:04:09,374 DEBUG   HandlerThread:7060 [handler.py:handle_request():146] handle_request: shutdown
2024-04-27 02:04:09,374 INFO    HandlerThread:7060 [handler.py:finish():866] shutting down handler
2024-04-27 02:04:09,472 INFO    WriterThread:7060 [datastore.py:close():296] close: E:\Codes\Projects\Introduction-to-Artificial-Intelligence\Classification\src\wandb\run-20240427_020406-ecmgq4d8\run-ecmgq4d8.wandb
2024-04-27 02:04:10,228 INFO    SenderThread:7060 [sender.py:finish():1546] shutting down sender
